Workbook

Sheet Leia-me
A1: Pauta do Sacolão × preços oficiais da CEASA-PR (Curitiba)
A3: Gerado em | B3: 19/10/2026
A4: Pauta | B4: Portaria 175/2026 da SMSAN — Diário Oficial Eletrônico nº 159, 26/08/2026 (republicação do DOM nº 156, que saiu sem o Anexo I). https://legisladocexterno.curitiba.pr.gov.br/AtosConsultaExternaDownload.aspx?Id=477144&tipo=ass
A5: Preços | B5: Cotação oficial da CEASA-PR (Divisão Técnica Econômica — DITEC), "preço mais comum" do dia por produto, tipo e embalagem, unidade Curitiba. São os mesmos valores do boletim "Coleta de Preços Diário" (https://www.ceasa.pr.gov.br/Pagina/Cotacao-Diaria-de-Precos-2026), coletados pela plataforma na consulta oficial de evolução de preços.
A6: Nomes dos produtos | B6: Calendário oficial de comercialização da CEASA-PR, unidade Curitiba (cópia em docs/ceasa/calendario_comercializacao_ceasa-pr_curitiba.pdf): ex.: Couve Manteiga, Brócolis, Tangerina Mimosa/Comum, Tangerina Murcot, Mandioca, Batata Salsa. Ele confirma as leituras do Anexo I (mimosa e murcot são tangerinas; brócolis, couve-flor e repolho estão entre as Hortaliças Folhosas). Boletim oficial de 19/10/2026 em docs/ceasa/coleta_precos_diario_curitiba_2026-10-19.pdf.
A7: Regra do preço de referência | B7: Para cada espécie da pauta entram TODOS os tipos oficiais do produto cotados em Curitiba na data mais recente (até 30 dias). Referência = mediana do preço mais comum por kg desses tipos; mínimo e máximo ao lado. Ficam fora: itens embalados ou minimamente processados (bandeja, pacote, fatiado, descascado, cenoura baby), que o Art. 2º da Portaria 175 trata fora da pauta; produtos que o boletim oficial lista à parte (Maçã Importada — inclui Granny Smith e Red Delicious —, Pera Importada, Batata Yakon); e tipos sem peso na embalagem (não têm R$/kg). Exceção: o milho-verde em saco de 50 espigas usa o peso de 13 kg informado no boletim oficial de 19/10/2026.
A8: Teto de comparação (R$/kg) | B8: 3.99
A9: Atenção ao teto | B9: R$ 3,99/kg era o teto da Resolução SMSAN nº 2/2024, REVOGADA pela Resolução SMSAN nº 2/2026 (DOM 179, 24/09/2026). A Portaria 175 (Art. 1º, §1º) diz que o preço máximo é definido por resolução específica, ainda não localizada. Edite a célula amarela para testar outro teto: as abas recalculam.
A10: Atacado × varejo | B10: Os preços da CEASA são de ATACADO; o teto vale para a venda ao consumidor no Sacolão. A comparação indica pressão de custo, não descumprimento.
A11: Abas | B11: Pauta 175 (86 linhas do Anexo I) · Referência por espécie (64 espécies, fórmulas) · Cotações CEASA (todos os tipos usados, com R$/kg calculado).
A12: Cores | B12: Azul em fundo amarelo = valor editável · Verde = valor trazido de outra aba · Preto = fórmula.

Sheet Pauta 175
A1: Estação | B1: Grupo | C1: Subgrupo | D1: Mínimo do subgrupo | E1: Espécie | F1: Variedade | G1: Texto no Anexo I | H1: R$/kg referência CEASA | I1: Acima do teto? | J1: Observação da transcrição
A2: Outono/Inverno | B2: Hortaliças | C2: Hortaliças Herbáceas (folhosas) | D2: 5 | E2: alface | G2: Alface | H2: =IFERROR(INDEX('Referência por espécie'!$E$2:$E$65,MATCH(E2&IF(F2="",""," "&F2),'Referência por espécie'!$B$2:$B$65,0)),"") -> 4.2857143 | I2: =IFERROR(INDEX('Referência por espécie'!$I$2:$I$65,MATCH(E2&IF(F2="",""," "&F2),'Referência por espécie'!$B$2:$B$65,0)),"") -> sim
A3: Outono/Inverno | B3: Hortaliças | C3: Hortaliças Herbáceas (folhosas) | D3: 5 | E3: alho-poró | G3: alho poró | H3: =IFERROR(INDEX('Referência por espécie'!$E$2:$E$65,MATCH(E3&IF(F3="",""," "&F3),'Referência por espécie'!$B$2:$B$65,0)),"") -> 7.5 | I3: =IFERROR(INDEX('Referência por espécie'!$I$2:$I$65,MATCH(E3&IF(F3="",""," "&F3),'Referência por espécie'!$B$2:$B$65,0)),"") -> sim
A4: Outono/Inverno | B4: Hortaliças | C4: Hortaliças Herbáceas (folhosas) | D4: 5 | E4: agrião | G4: agrião | H4: =IFERROR(INDEX('Referência por espécie'!$E$2:$E$65,MATCH(E4&IF(F4="",""," "&F4),'Referência por espécie'!$B$2:$B$65,0)),"") -> 6.25 | I4: =IFERROR(INDEX('Referência por espécie'!$I$2:$I$65,MATCH(E4&IF(F4="",""," "&F4),'Referência por espécie'!$B$2:$B$65,0)),"") -> sim
A5: Outono/Inverno | B5: Hortaliças | C5: Hortaliças Herbáceas (folhosas) | D5: 5 | E5: almeirão | G5: almeirão | H5: =IFERROR(INDEX('Referência por espécie'!$E$2:$E$65,MATCH(E5&IF(F5="",""," "&F5),'Referência por espécie'!$B$2:$B$65,0)),"") -> 5.8333333 | I5: =IFERROR(INDEX('Referência por espécie'!$I$2:$I$65,MATCH(E5&IF(F5="",""," "&F5),'Referência por espécie'!$B$2:$B$65,0)),"") -> sim
A6: Outono/Inverno | B6: Hortaliças | C6: Hortaliças Herbáceas (folhosas) | D6: 5 | E6: couve-flor | G6: couve-flor | H6: =IFERROR(INDEX('Referência por espécie'!$E$2:$E$65,MATCH(E6&IF(F6="",""," "&F6),'Referência por espécie'!$B$2:$B$65,0)),"") -> 1.6666667 | I6: =IFERROR(INDEX('Referência por espécie'!$I$2:$I$65,MATCH(E6&IF(F6="",""," "&F6),'Referência por espécie'!$B$2:$B$65,0)),"") -> não | J6: brássica entre as folhosas, como no calendário oficial da CEASA-PR (Curitiba) (Hortaliças Folhosas) — confirmado
A7: Outono/Inverno | B7: Hortaliças | C7: Hortaliças Herbáceas (folhosas) | D7: 5 | E7: brócolis | G7: couve- brócolis | H7: =IFERROR(INDEX('Referência por espécie'!$E$2:$E$65,MATCH(E7&IF(F7="",""," "&F7),'Referência por espécie'!$B$2:$B$65,0)),"") -> 5.9166667 | I7: =IFERROR(INDEX('Referência por espécie'!$I$2:$I$65,MATCH(E7&IF(F7="",""," "&F7),'Referência por espécie'!$B$2:$B$65,0)),"") -> sim | J7: anexo grafa 'couve- brócolis'; o calendário oficial da CEASA-PR (Curitiba) lista 'Brócolis' entre as Hortaliças Folhosas — confirmado
A8: Outono/Inverno | B8: Hortaliças | C8: Hortaliças Herbáceas (folhosas) | D8: 5 | E8: couve | G8: couve | H8: =IFERROR(INDEX('Referência por espécie'!$E$2:$E$65,MATCH(E8&IF(F8="",""," "&F8),'Referência por espécie'!$B$2:$B$65,0)),"") -> 5 | I8: =IFERROR(INDEX('Referência por espécie'!$I$2:$I$65,MATCH(E8&IF(F8="",""," "&F8),'Referência por espécie'!$B$2:$B$65,0)),"") -> sim | J8: o anexo traz um item vazio logo depois (', ,'), ignorado
A9: Outono/Inverno | B9: Hortaliças | C9: Hortaliças Herbáceas (folhosas) | D9: 5 | E9: couve chinesa | G9: couve chinesa | H9: =IFERROR(INDEX('Referência por espécie'!$E$2:$E$65,MATCH(E9&IF(F9="",""," "&F9),'Referência por espécie'!$B$2:$B$65,0)),"") -> 2 | I9: =IFERROR(INDEX('Referência por espécie'!$I$2:$I$65,MATCH(E9&IF(F9="",""," "&F9),'Referência por espécie'!$B$2:$B$65,0)),"") -> não
A10: Outono/Inverno | B10: Hortaliças | C10: Hortaliças Herbáceas (folhosas) | D10: 5 | E10: cheiro-verde | G10: cheiro-verde | H10: =IFERROR(INDEX('Referência por espécie'!$E$2:$E$65,MATCH(E10&IF(F10="",""," "&F10),'Referência por espécie'!$B$2:$B$65,0)),"") -> 10 | I10: =IFERROR(INDEX('Referência por espécie'!$I$2:$I$65,MATCH(E10&IF(F10="",""," "&F10),'Referência por espécie'!$B$2:$B$65,0)),"") -> sim
A11: Outono/Inverno | B11: Hortaliças | C11: Hortaliças Herbáceas (folhosas) | D11: 5 | E11: escarola | G11: escarola | H11: =IFERROR(INDEX('Referência por espécie'!$E$2:$E$65,MATCH(E11&IF(F11="",""," "&F11),'Referência por espécie'!$B$2:$B$65,0)),"") -> 5 | I11: =IFERROR(INDEX('Referência por espécie'!$I$2:$I$65,MATCH(E11&IF(F11="",""," "&F11),'Referência por espécie'!$B$2:$B$65,0)),"") -> sim
A12: Outono/Inverno | B12: Hortaliças | C12: Hortaliças Herbáceas (folhosas) | D12: 5 | E12: espinafre | G12: espinafre | H12: =IFERROR(INDEX('Referência por espécie'!$E$2:$E$65,MATCH(E12&IF(F12="",""," "&F12),'Referência por espécie'!$B$2:$B$65,0)),"") -> 6.25 | I12: =IFERROR(INDEX('Referência por espécie'!$I$2:$I$65,MATCH(E12&IF(F12="",""," "&F12),'Referência por espécie'!$B$2:$B$65,0)),"") -> sim
A13: Outono/Inverno | B13: Hortaliças | C13: Hortaliças Herbáceas (folhosas) | D13: 5 | E13: mostarda | G13: mostarda | H13: =IFERROR(INDEX('Referência por espécie'!$E$2:$E$65,MATCH(E13&IF(F13="",""," "&F13),'Referência por espécie'!$B$2:$B$65,0)),"") -> 5 | I13: =IFERROR(INDEX('Referência por espécie'!$I$2:$I$65,MATCH(E13&IF(F13="",""," "&F13),'Referência por espécie'!$B$2:$B$65,0)),"") -> sim
A14: Outono/Inverno | B14: Hortaliças | C14: Hortaliças Herbáceas (folhosas) | D14: 5 | E14: rúcula | G14: rúcula | H14: =IFERROR(INDEX('Referência por espécie'!$E$2:$E$65,MATCH(E14&IF(F14="",""," "&F14),'Referência por espécie'!$B$2:$B$65,0)),"") -> 7.5 | I14: =IFERROR(INDEX('Referência por espécie'!$I$2:$I$65,MATCH(E14&IF(F14="",""," "&F14),'Referência por espécie'!$B$2:$B$65,0)),"") -> sim
A15: Outono/Inverno | B15: Hortaliças | C15: Hortaliças Frutos | D15: 2 | E15: abóbora | G15: Abóbora | H15: =IFERROR(INDEX('Referência por espécie'!$E$2:$E$65,MATCH(E15&IF(F15="",""," "&F15),'Referência por espécie'!$B$2:$B$65,0)),"") -> 2.125 | I15: =IFERROR(INDEX('Referência por espécie'!$I$2:$I$65,MATCH(E15&IF(F15="",""," "&F15),'Referência por espécie'!$B$2:$B$65,0)),"") -> não
A16: Outono/Inverno | B16: Hortaliças | C16: Hortaliças Frutos | D16: 2 | E16: chuchu | G16: chuchu | H16: =IFERROR(INDEX('Referência por espécie'!$E$2:$E$65,MATCH(E16&IF(F16="",""," "&F16),'Referência por espécie'!$B$2:$B$65,0)),"") -> 1.75 | I16: =IFERROR(INDEX('Referência por espécie'!$I$2:$I$65,MATCH(E16&IF(F16="",""," "&F16),'Referência por espécie'!$B$2:$B$65,0)),"") -> não
A17: Outono/Inverno | B17: Hortaliças | C17: Hortaliças Frutos | D17: 2 | E17: ervilha | G17: ervilha | H17: =IFERROR(INDEX('Referência por espécie'!$E$2:$E$65,MATCH(E17&IF(F17="",""," "&F17),'Referência por espécie'!$B$2:$B$65,0)),"") -> 12.5 | I17: =IFERROR(INDEX('Referência por espécie'!$I$2:$I$65,MATCH(E17&IF(F17="",""," "&F17),'Referência por espécie'!$B$2:$B$65,0)),"") -> sim
A18: Outono/Inverno | B18: Hortaliças | C18: Hortaliças Raízes, tuberosas e bulbos | D18: 10 | E18: aipim | G18: Aipim | H18: =IFERROR(INDEX('Referência por espécie'!$E$2:$E$65,MATCH(E18&IF(F18="",""," "&F18),'Referência por espécie'!$B$2:$B$65,0)),"") -> 2.5 | I18: =IFERROR(INDEX('Referência por espécie'!$I$2:$I$65,MATCH(E18&IF(F18="",""," "&F18),'Referência por espécie'!$B$2:$B$65,0)),"") -> não
A19: Outono/Inverno | B19: Hortaliças | C19: Hortaliças Raízes, tuberosas e bulbos | D19: 10 | E19: batata | G19: batata | H19: =IFERROR(INDEX('Referência por espécie'!$E$2:$E$65,MATCH(E19&IF(F19="",""," "&F19),'Referência por espécie'!$B$2:$B$65,0)),"") -> 4.4 | I19: =IFERROR(INDEX('Referência por espécie'!$I$2:$I$65,MATCH(E19&IF(F19="",""," "&F19),'Referência por espécie'!$B$2:$B$65,0)),"") -> sim
A20: Outono/Inverno | B20: Hortaliças | C20: Hortaliças Raízes, tuberosas e bulbos | D20: 10 | E20: batata-doce | G20: batata-doce | H20: =IFERROR(INDEX('Referência por espécie'!$E$2:$E$65,MATCH(E20&IF(F20="",""," "&F20),'Referência por espécie'!$B$2:$B$65,0)),"") -> 3.25 | I20: =IFERROR(INDEX('Referência por espécie'!$I$2:$I$65,MATCH(E20&IF(F20="",""," "&F20),'Referência por espécie'!$B$2:$B$65,0)),"") -> não
... A25: Outono/Inverno | B25: Hortaliças | C25: Hortaliças Raízes, tuberosas e bulbos | D25: 10 | E25: inhame | G25: inhame | H25: =IFERROR(INDEX('Referência por espécie'!$E$2:$E$65,MATCH(E25&IF(F25="",""," "&F25),'Referência por espécie'!$B$2:$B$65,0)),"") -> 4 | I25: =IFERROR(INDEX('Referência por espécie'!$I$2:$I$65,MATCH(E25&IF(F25="",""," "&F25),'Referência por espécie'!$B$2:$B$65,0)),"") -> sim
A26: Outono/Inverno | B26: Hortaliças | C26: Hortaliças Raízes, tuberosas e bulbos | D26: 10 | E26: nabo | G26: nabo e mandioquinha-salsa | H26: =IFERROR(INDEX('Referência por espécie'!$E$2:$E$65,MATCH(E26&IF(F26="",""," "&F26),'Referência por espécie'!$B$2:$B$65,0)),"") -> 2.2604167 | I26: =IFERROR(INDEX('Referência por espécie'!$I$2:$I$65,MATCH(E26&IF(F26="",""," "&F26),'Referência por espécie'!$B$2:$B$65,0)),"") -> não | J26: lida como duas espécies separadas por 'e'; o calendário oficial da CEASA-PR (Curitiba) lista as duas separadas
A27: Outono/Inverno | B27: Hortaliças | C27: Hortaliças Raízes, tuberosas e bulbos | D27: 10 | E27: mandioquinha-salsa | G27: nabo e mandioquinha-salsa | H27: =IFERROR(INDEX('Referência por espécie'!$E$2:$E$65,MATCH(E27&IF(F27="",""," "&F27),'Referência por espécie'!$B$2:$B$65,0)),"") -> 3.0475 | I27: =IFERROR(INDEX('Referência por espécie'!$I$2:$I$65,MATCH(E27&IF(F27="",""," "&F27),'Referência por espécie'!$B$2:$B$65,0)),"") -> não | J27: lida como duas espécies separadas por 'e'; o calendário oficial da CEASA-PR (Curitiba) lista as duas separadas
A28: Outono/Inverno | B28: Hortaliças | C28: Hortaliças Raízes, tuberosas e bulbos | D28: 10 | E28: rabanete | G28: rabanete | H28: =IFERROR(INDEX('Referência por espécie'!$E$2:$E$65,MATCH(E28&IF(F28="",""," "&F28),'Referência por espécie'!$B$2:$B$65,0)),"") -> 2.75 | I28: =IFERROR(INDEX('Referência por espécie'!$I$2:$I$65,MATCH(E28&IF(F28="",""," "&F28),'Referência por espécie'!$B$2:$B$65,0)),"") -> não
A29: Outono/Inverno | B29: Frutas | C29: Frutas | D29: 6 | E29: abacate | G29: Abacate | H29: =IFERROR(INDEX('Referência por espécie'!$E$2:$E$65,MATCH(E29&IF(F29="",""," "&F29),'Referência por espécie'!$B$2:$B$65,0)),"") -> 6 | I29: =IFERROR(INDEX('Referência por espécie'!$I$2:$I$65,MATCH(E29&IF(F29="",""," "&F29),'Referência por espécie'!$B$2:$B$65,0)),"") -> sim
A30: Outono/Inverno | B30: Frutas | C30: Frutas | D30: 6 | E30: banana | G30: banana | H30: =IFERROR(INDEX('Referência por espécie'!$E$2:$E$65,MATCH(E30&IF(F30="",""," "&F30),'Referência por espécie'!$B$2:$B$65,0)),"") -> 2.5 | I30: =IFERROR(INDEX('Referência por espécie'!$I$2:$I$65,MATCH(E30&IF(F30="",""," "&F30),'Referência por espécie'!$B$2:$B$65,0)),"") -> não
A31: Outono/Inverno | B31: Frutas | C31: Frutas | D31: 6 | E31: caqui | G31: caqui | H31: =IFERROR(INDEX('Referência por espécie'!$E$2:$E$65,MATCH(E31&IF(F31="",""," "&F31),'Referência por espécie'!$B$2:$B$65,0)),"") -> 8.125 | I31: =IFERROR(INDEX('Referência por espécie'!$I$2:$I$65,MATCH(E31&IF(F31="",""," "&F31),'Referência por espécie'!$B$2:$B$65,0)),"") -> sim
A32: Outono/Inverno | B32: Frutas | C32: Frutas | D32: 6 | E32: carambola | G32: ca r am bo la | H32: =IFERROR(INDEX('Referência por espécie'!$E$2:$E$65,MATCH(E32&IF(F32="",""," "&F32),'Referência por espécie'!$B$2:$B$65,0)),"") -> 13.333333 | I32: =IFERROR(INDEX('Referência por espécie'!$I$2:$I$65,MATCH(E32&IF(F32="",""," "&F32),'Referência por espécie'!$B$2:$B$65,0)),"") -> sim | J32: espaçamento do PDF corrigido
A33: Outono/Inverno | B33: Frutas | C33: Frutas | D33: 6 | E33: kiwi | G33: kiwi | H33: =IFERROR(INDEX('Referência por espécie'!$E$2:$E$65,MATCH(E33&IF(F33="",""," "&F33),'Referência por espécie'!$B$2:$B$65,0)),"") -> 24 | I33: =IFERROR(INDEX('Referência por espécie'!$I$2:$I$65,MATCH(E33&IF(F33="",""," "&F33),'Referência por espécie'!$B$2:$B$65,0)),"") -> sim
A34: Outono/Inverno | B34: Frutas | C34: Frutas | D34: 6 | E34: maçã | G34: maçã | H34: =IFERROR(INDEX('Referência por espécie'!$E$2:$E$65,MATCH(E34&IF(F34="",""," "&F34),'Referência por espécie'!$B$2:$B$65,0)),"") -> 6.1111111 | I34: =IFERROR(INDEX('Referência por espécie'!$I$2:$I$65,MATCH(E34&IF(F34="",""," "&F34),'Referência por espécie'!$B$2:$B$65,0)),"") -> sim
A35: Outono/Inverno | B35: Frutas | C35: Frutas | D35: 6 | E35: mamão | G35: mamão | H35: =IFERROR(INDEX('Referência por espécie'!$E$2:$E$65,MATCH(E35&IF(F35="",""," "&F35),'Referência por espécie'!$B$2:$B$65,0)),"") -> 5.66 | I35: =IFERROR(INDEX('Referência por espécie'!$I$2:$I$65,MATCH(E35&IF(F35="",""," "&F35),'Referência por espécie'!$B$2:$B$65,0)),"") -> sim
A36: Outono/Inverno | B36: Frutas | C36: Frutas | D36: 6 | E36: maracujá | G36: maracujá | H36: =IFERROR(INDEX('Referência por espécie'!$E$2:$E$65,MATCH(E36&IF(F36="",""," "&F36),'Referência por espécie'!$B$2:$B$65,0)),"") -> 21.25 | I36: =IFERROR(INDEX('Referência por espécie'!$I$2:$I$65,MATCH(E36&IF(F36="",""," "&F36),'Referência por espécie'!$B$2:$B$65,0)),"") -> sim
A37: Outono/Inverno | B37: Frutas | C37: Frutas | D37: 6 | E37: melão | G37: melão | H37: =IFERROR(INDEX('Referência por espécie'!$E$2:$E$65,MATCH(E37&IF(F37="",""," "&F37),'Referência por espécie'!$B$2:$B$65,0)),"") -> 6.1538462 | I37: =IFERROR(INDEX('Referência por espécie'!$I$2:$I$65,MATCH(E37&IF(F37="",""," "&F37),'Referência por espécie'!$B$2:$B$65,0)),"") -> sim
A38: Outono/Inverno | B38: Frutas | C38: Frutas Cítricas | D38: 3 | E38: laranja | F38: pera | G38: Laranja pera | H38: =IFERROR(INDEX('Referência por espécie'!$E$2:$E$65,MATCH(E38&IF(F38="",""," "&F38),'Referência por espécie'!$B$2:$B$65,0)),"") -> 2.5 | I38: =IFERROR(INDEX('Referência por espécie'!$I$2:$I$65,MATCH(E38&IF(F38="",""," "&F38),'Referência por espécie'!$B$2:$B$65,0)),"") -> não
A39: Outono/Inverno | B39: Frutas | C39: Frutas Cítricas | D39: 3 | E39: laranja | F39: lima | G39: laranja lima | H39: =IFERROR(INDEX('Referência por espécie'!$E$2:$E$65,MATCH(E39&IF(F39="",""," "&F39),'Referência por espécie'!$B$2:$B$65,0)),"") -> 4.25 | I39: =IFERROR(INDEX('Referência por espécie'!$I$2:$I$65,MATCH(E39&IF(F39="",""," "&F39),'Referência por espécie'!$B$2:$B$65,0)),"") -> sim
A40: Outono/Inverno | B40: Frutas | C40: Frutas Cítricas | D40: 3 | E40: limão | F40: rosa | G40: limão rosa | H40: =IFERROR(INDEX('Referência por espécie'!$E$2:$E$65,MATCH(E40&IF(F40="",""," "&F40),'Referência por espécie'!$B$2:$B$65,0)),"") -> 2.5 | I40: =IFERROR(INDEX('Referência por espécie'!$I$2:$I$65,MATCH(E40&IF(F40="",""," "&F40),'Referência por espécie'!$B$2:$B$65,0)),"") -> não
A41: Outono/Inverno | B41: Frutas | C41: Frutas Cítricas | D41: 3 | E41: limão | F41: tahiti | G41: limão tahiti | H41: =IFERROR(INDEX('Referência por espécie'!$E$2:$E$65,MATCH(E41&IF(F41="",""," "&F41),'Referência por espécie'!$B$2:$B$65,0)),"") -> 8.6956522 | I41: =IFERROR(INDEX('Referência por espécie'!$I$2:$I$65,MATCH(E41&IF(F41="",""," "&F41),'Referência por espécie'!$B$2:$B$65,0)),"") -> sim
A42: Outono/Inverno | B42: Frutas | C42: Frutas Cítricas | D42: 3 | E42: tangerina | F42: ponkan | G42: tangerina ponkan | H42: =IFERROR(INDEX('Referência por espécie'!$E$2:$E$65,MATCH(E42&IF(F42="",""," "&F42),'Referência por espécie'!$B$2:$B$65,0)),"") -> 5 | I42: =IFERROR(INDEX('Referência por espécie'!$I$2:$I$65,MATCH(E42&IF(F42="",""," "&F42),'Referência por espécie'!$B$2:$B$65,0)),"") -> sim
A43: Outono/Inverno | B43: Frutas | C43: Frutas Cítricas | D43: 3 | E43: tangerina | F43: mimosa | G43: mimosa | H43: =IFERROR(INDEX('Referência por espécie'!$E$2:$E$65,MATCH(E43&IF(F43="",""," "&F43),'Referência por espécie'!$B$2:$B$65,0)),"") -> 2.5 | I43: =IFERROR(INDEX('Referência por espécie'!$I$2:$I$65,MATCH(E43&IF(F43="",""," "&F43),'Referência por espécie'!$B$2:$B$65,0)),"") -> não | J43: 'mimosa' aparece sozinha na lista de cítricas; o calendário oficial da CEASA-PR (Curitiba) lista 'Tangerina Mimosa/Comum' (mexerica) — confirmado; antes interpretada como tangerina mimosa (mexerica)
A44: Outono/Inverno | B44: Frutas | C44: Frutas Cítricas | D44: 3 | E44: tangerina | F44: murcote | G44: murcot | H44: =IFERROR(INDEX('Referência por espécie'!$E$2:$E$65,MATCH(E44&IF(F44="",""," "&F44),'Referência por espécie'!$B$2:$B$65,0)),"") -> 4.7826087 | I44: =IFERROR(INDEX('Referência por espécie'!$I$2:$I$65,MATCH(E44&IF(F44="",""," "&F44),'Referência por espécie'!$B$2:$B$65,0)),"") -> sim | J44: lida como tangerina; grafia do anexo 'murcot'; o calendário oficial da CEASA-PR (Curitiba) lista 'Tangerina Murcot' — confirmado
...

Sheet Referência por espécie
A1: Subgrupo | B1: Espécie da pauta | C1: Estações | D1: Tipos oficiais cotados | E1: R$/kg referência (mediana) | F1: R$/kg mínimo | G1: R$/kg máximo | H1: Data da cotação | I1: Acima do teto? | J1: Situação
A2: Hortaliças Herbáceas (folhosas) | B2: agrião | C2: Out/Inv + Prim/Ver | D2: =COUNTIFS('Cotações CEASA'!$A$2:$A$124,B2) -> 1 | E2: {=IF(D2=0,"",MEDIAN(IF('Cotações CEASA'!$A$2:$A$124=B2,'Cotações CEASA'!$F$2:$F$124)))} -> 6.25 | F2: =IF(D2=0,"",_xlfn.MINIFS('Cotações CEASA'!$F$2:$F$124,'Cotações CEASA'!$A$2:$A$124,B2)) -> 6.25 | G2: =IF(D2=0,"",_xlfn.MAXIFS('Cotações CEASA'!$F$2:$F$124,'Cotações CEASA'!$A$2:$A$124,B2)) -> 6.25 | H2: =IF(D2=0,"",_xlfn.MAXIFS('Cotações CEASA'!$G$2:$G$124,'Cotações CEASA'!$A$2:$A$124,B2)) -> 46310 | I2: =IF(E2="","",IF(E2>'Leia-me'!$B$8,"sim","não")) -> sim | J2: =IF(D2=0,"sem cotação em 30 dias","cotado") -> cotado
A3: Hortaliças Herbáceas (folhosas) | B3: alface | C3: Out/Inv + Prim/Ver | D3: =COUNTIFS('Cotações CEASA'!$A$2:$A$124,B3) -> 6 | E3: {=IF(D3=0,"",MEDIAN(IF('Cotações CEASA'!$A$2:$A$124=B3,'Cotações CEASA'!$F$2:$F$124)))} -> 4.2857143 | F3: =IF(D3=0,"",_xlfn.MINIFS('Cotações CEASA'!$F$2:$F$124,'Cotações CEASA'!$A$2:$A$124,B3)) -> 3.3333333 | G3: =IF(D3=0,"",_xlfn.MAXIFS('Cotações CEASA'!$F$2:$F$124,'Cotações CEASA'!$A$2:$A$124,B3)) -> 5 | H3: =IF(D3=0,"",_xlfn.MAXIFS('Cotações CEASA'!$G$2:$G$124,'Cotações CEASA'!$A$2:$A$124,B3)) -> 46310 | I3: =IF(E3="","",IF(E3>'Leia-me'!$B$8,"sim","não")) -> sim | J3: =IF(D3=0,"sem cotação em 30 dias","cotado") -> cotado
A4: Hortaliças Herbáceas (folhosas) | B4: alho-poró | C4: Out/Inv | D4: =COUNTIFS('Cotações CEASA'!$A$2:$A$124,B4) -> 1 | E4: {=IF(D4=0,"",MEDIAN(IF('Cotações CEASA'!$A$2:$A$124=B4,'Cotações CEASA'!$F$2:$F$124)))} -> 7.5 | F4: =IF(D4=0,"",_xlfn.MINIFS('Cotações CEASA'!$F$2:$F$124,'Cotações CEASA'!$A$2:$A$124,B4)) -> 7.5 | G4: =IF(D4=0,"",_xlfn.MAXIFS('Cotações CEASA'!$F$2:$F$124,'Cotações CEASA'!$A$2:$A$124,B4)) -> 7.5 | H4: =IF(D4=0,"",_xlfn.MAXIFS('Cotações CEASA'!$G$2:$G$124,'Cotações CEASA'!$A$2:$A$124,B4)) -> 46310 | I4: =IF(E4="","",IF(E4>'Leia-me'!$B$8,"sim","não")) -> sim | J4: =IF(D4=0,"sem cotação em 30 dias","cotado") -> cotado
A5: Hortaliças Herbáceas (folhosas) | B5: almeirão | C5: Out/Inv + Prim/Ver | D5: =COUNTIFS('Cotações CEASA'!$A$2:$A$124,B5) -> 2 | E5: {=IF(D5=0,"",MEDIAN(IF('Cotações CEASA'!$A$2:$A$124=B5,'Cotações CEASA'!$F$2:$F$124)))} -> 5.8333333 | F5: =IF(D5=0,"",_xlfn.MINIFS('Cotações CEASA'!$F$2:$F$124,'Cotações CEASA'!$A$2:$A$124,B5)) -> 5 | G5: =IF(D5=0,"",_xlfn.MAXIFS('Cotações CEASA'!$F$2:$F$124,'Cotações CEASA'!$A$2:$A$124,B5)) -> 6.6666667 | H5: =IF(D5=0,"",_xlfn.MAXIFS('Cotações CEASA'!$G$2:$G$124,'Cotações CEASA'!$A$2:$A$124,B5)) -> 46310 | I5: =IF(E5="","",IF(E5>'Leia-me'!$B$8,"sim","não")) -> sim | J5: =IF(D5=0,"sem cotação em 30 dias","cotado") -> cotado
A6: Hortaliças Herbáceas (folhosas) | B6: brócolis | C6: Out/Inv | D6: =COUNTIFS('Cotações CEASA'!$A$2:$A$124,B6) -> 2 | E6: {=IF(D6=0,"",MEDIAN(IF('Cotações CEASA'!$A$2:$A$124=B6,'Cotações CEASA'!$F$2:$F$124)))} -> 5.9166667 | F6: =IF(D6=0,"",_xlfn.MINIFS('Cotações CEASA'!$F$2:$F$124,'Cotações CEASA'!$A$2:$A$124,B6)) -> 5.8333333 | G6: =IF(D6=0,"",_xlfn.MAXIFS('Cotações CEASA'!$F$2:$F$124,'Cotações CEASA'!$A$2:$A$124,B6)) -> 6 | H6: =IF(D6=0,"",_xlfn.MAXIFS('Cotações CEASA'!$G$2:$G$124,'Cotações CEASA'!$A$2:$A$124,B6)) -> 46310 | I6: =IF(E6="","",IF(E6>'Leia-me'!$B$8,"sim","não")) -> sim | J6: =IF(D6=0,"sem cotação em 30 dias","cotado") -> cotado
A7: Hortaliças Herbáceas (folhosas) | B7: cheiro-verde | C7: Out/Inv + Prim/Ver | D7: =COUNTIFS('Cotações CEASA'!$A$2:$A$124,B7) -> 1 | E7: {=IF(D7=0,"",MEDIAN(IF('Cotações CEASA'!$A$2:$A$124=B7,'Cotações CEASA'!$F$2:$F$124)))} -> 10 | F7: =IF(D7=0,"",_xlfn.MINIFS('Cotações CEASA'!$F$2:$F$124,'Cotações CEASA'!$A$2:$A$124,B7)) -> 10 | G7: =IF(D7=0,"",_xlfn.MAXIFS('Cotações CEASA'!$F$2:$F$124,'Cotações CEASA'!$A$2:$A$124,B7)) -> 10 | H7: =IF(D7=0,"",_xlfn.MAXIFS('Cotações CEASA'!$G$2:$G$124,'Cotações CEASA'!$A$2:$A$124,B7)) -> 46310 | I7: =IF(E7="","",IF(E7>'Leia-me'!$B$8,"sim","não")) -> sim | J7: =IF(D7=0,"sem cotação em 30 dias","cotado") -> cotado
A8: Hortaliças Herbáceas (folhosas) | B8: couve | C8: Out/Inv + Prim/Ver | D8: =COUNTIFS('Cotações CEASA'!$A$2:$A$124,B8) -> 1 | E8: {=IF(D8=0,"",MEDIAN(IF('Cotações CEASA'!$A$2:$A$124=B8,'Cotações CEASA'!$F$2:$F$124)))} -> 5 | F8: =IF(D8=0,"",_xlfn.MINIFS('Cotações CEASA'!$F$2:$F$124,'Cotações CEASA'!$A$2:$A$124,B8)) -> 5 | G8: =IF(D8=0,"",_xlfn.MAXIFS('Cotações CEASA'!$F$2:$F$124,'Cotações CEASA'!$A$2:$A$124,B8)) -> 5 | H8: =IF(D8=0,"",_xlfn.MAXIFS('Cotações CEASA'!$G$2:$G$124,'Cotações CEASA'!$A$2:$A$124,B8)) -> 46310 | I8: =IF(E8="","",IF(E8>'Leia-me'!$B$8,"sim","não")) -> sim | J8: =IF(D8=0,"sem cotação em 30 dias","cotado") -> cotado
A9: Hortaliças Herbáceas (folhosas) | B9: couve chinesa | C9: Out/Inv | D9: =COUNTIFS('Cotações CEASA'!$A$2:$A$124,B9) -> 3 | E9: {=IF(D9=0,"",MEDIAN(IF('Cotações CEASA'!$A$2:$A$124=B9,'Cotações CEASA'!$F$2:$F$124)))} -> 2 | F9: =IF(D9=0,"",_xlfn.MINIFS('Cotações CEASA'!$F$2:$F$124,'Cotações CEASA'!$A$2:$A$124,B9)) -> 1.6666667 | G9: =IF(D9=0,"",_xlfn.MAXIFS('Cotações CEASA'!$F$2:$F$124,'Cotações CEASA'!$A$2:$A$124,B9)) -> 2.3333333 | H9: =IF(D9=0,"",_xlfn.MAXIFS('Cotações CEASA'!$G$2:$G$124,'Cotações CEASA'!$A$2:$A$124,B9)) -> 46310 | I9: =IF(E9="","",IF(E9>'Leia-me'!$B$8,"sim","não")) -> não | J9: =IF(D9=0,"sem cotação em 30 dias","cotado") -> cotado
A10: Hortaliças Herbáceas (folhosas) | B10: couve-flor | C10: Out/Inv | D10: =COUNTIFS('Cotações CEASA'!$A$2:$A$124,B10) -> 3 | E10: {=IF(D10=0,"",MEDIAN(IF('Cotações CEASA'!$A$2:$A$124=B10,'Cotações CEASA'!$F$2:$F$124)))} -> 1.6666667 | F10: =IF(D10=0,"",_xlfn.MINIFS('Cotações CEASA'!$F$2:$F$124,'Cotações CEASA'!$A$2:$A$124,B10)) -> 1.5 | G10: =IF(D10=0,"",_xlfn.MAXIFS('Cotações CEASA'!$F$2:$F$124,'Cotações CEASA'!$A$2:$A$124,B10)) -> 3.3333333 | H10: =IF(D10=0,"",_xlfn.MAXIFS('Cotações CEASA'!$G$2:$G$124,'Cotações CEASA'!$A$2:$A$124,B10)) -> 46310 | I10: =IF(E10="","",IF(E10>'Leia-me'!$B$8,"sim","não")) -> não | J10: =IF(D10=0,"sem cotação em 30 dias","cotado") -> cotado
A11: Hortaliças Herbáceas (folhosas) | B11: escarola | C11: Out/Inv + Prim/Ver | D11: =COUNTIFS('Cotações CEASA'!$A$2:$A$124,B11) -> 1 | E11: {=IF(D11=0,"",MEDIAN(IF('Cotações CEASA'!$A$2:$A$124=B11,'Cotações CEASA'!$F$2:$F$124)))} -> 5 | F11: =IF(D11=0,"",_xlfn.MINIFS('Cotações CEASA'!$F$2:$F$124,'Cotações CEASA'!$A$2:$A$124,B11)) -> 5 | G11: =IF(D11=0,"",_xlfn.MAXIFS('Cotações CEASA'!$F$2:$F$124,'Cotações CEASA'!$A$2:$A$124,B11)) -> 5 | H11: =IF(D11=0,"",_xlfn.MAXIFS('Cotações CEASA'!$G$2:$G$124,'Cotações CEASA'!$A$2:$A$124,B11)) -> 46310 | I11: =IF(E11="","",IF(E11>'Leia-me'!$B$8,"sim","não")) -> sim | J11: =IF(D11=0,"sem cotação em 30 dias","cotado") -> cotado
A12: Hortaliças Herbáceas (folhosas) | B12: espinafre | C12: Out/Inv | D12: =COUNTIFS('Cotações CEASA'!$A$2:$A$124,B12) -> 1 | E12: {=IF(D12=0,"",MEDIAN(IF('Cotações CEASA'!$A$2:$A$124=B12,'Cotações CEASA'!$F$2:$F$124)))} -> 6.25 | F12: =IF(D12=0,"",_xlfn.MINIFS('Cotações CEASA'!$F$2:$F$124,'Cotações CEASA'!$A$2:$A$124,B12)) -> 6.25 | G12: =IF(D12=0,"",_xlfn.MAXIFS('Cotações CEASA'!$F$2:$F$124,'Cotações CEASA'!$A$2:$A$124,B12)) -> 6.25 | H12: =IF(D12=0,"",_xlfn.MAXIFS('Cotações CEASA'!$G$2:$G$124,'Cotações CEASA'!$A$2:$A$124,B12)) -> 46310 | I12: =IF(E12="","",IF(E12>'Leia-me'!$B$8,"sim","não")) -> sim | J12: =IF(D12=0,"sem cotação em 30 dias","cotado") -> cotado
A13: Hortaliças Herbáceas (folhosas) | B13: mostarda | C13: Out/Inv | D13: =COUNTIFS('Cotações CEASA'!$A$2:$A$124,B13) -> 1 | E13: {=IF(D13=0,"",MEDIAN(IF('Cotações CEASA'!$A$2:$A$124=B13,'Cotações CEASA'!$F$2:$F$124)))} -> 5 | F13: =IF(D13=0,"",_xlfn.MINIFS('Cotações CEASA'!$F$2:$F$124,'Cotações CEASA'!$A$2:$A$124,B13)) -> 5 | G13: =IF(D13=0,"",_xlfn.MAXIFS('Cotações CEASA'!$F$2:$F$124,'Cotações CEASA'!$A$2:$A$124,B13)) -> 5 | H13: =IF(D13=0,"",_xlfn.MAXIFS('Cotações CEASA'!$G$2:$G$124,'Cotações CEASA'!$A$2:$A$124,B13)) -> 46310 | I13: =IF(E13="","",IF(E13>'Leia-me'!$B$8,"sim","não")) -> sim | J13: =IF(D13=0,"sem cotação em 30 dias","cotado") -> cotado
... A65: Frutas Cítricas | B65: tangerina ponkan | C65: Out/Inv | D65: =COUNTIFS('Cotações CEASA'!$A$2:$A$124,B65) -> 1 | E65: {=IF(D65=0,"",MEDIAN(IF('Cotações CEASA'!$A$2:$A$124=B65,'Cotações CEASA'!$F$2:$F$124)))} -> 5 | F65: =IF(D65=0,"",_xlfn.MINIFS('Cotações CEASA'!$F$2:$F$124,'Cotações CEASA'!$A$2:$A$124,B65)) -> 5 | G65: =IF(D65=0,"",_xlfn.MAXIFS('Cotações CEASA'!$F$2:$F$124,'Cotações CEASA'!$A$2:$A$124,B65)) -> 5 | H65: =IF(D65=0,"",_xlfn.MAXIFS('Cotações CEASA'!$G$2:$G$124,'Cotações CEASA'!$A$2:$A$124,B65)) -> 46310 | I65: =IF(E65="","",IF(E65>'Leia-me'!$B$8,"sim","não")) -> sim | J65: =IF(D65=0,"sem cotação em 30 dias","cotado") -> cotado
B67: Espécies com cotação | E67: =COUNTIF(J2:J65,"cotado") -> 64
B68: Espécies acima do teto | E68: =COUNTIF(I2:I65,"sim") -> 45
B69: Teto usado na comparação (R$/kg) | E69: ='Leia-me'!$B$8 -> 3.99

Sheet Cotações CEASA
A1: Espécie da pauta | B1: Descrição oficial (CEASA-PR) | C1: Embalagem | D1: Peso da embalagem (kg) | E1: Preço mais comum (R$/embalagem) | F1: R$/kg | G1: Data da cotação
A2: agrião | B2: AGRIAO mç 400 g | C2: mç 400 g | D2: 0.4 | E2: 2.5 | F2: =E2/D2 -> 6.25 | G2: 46310
A3: alface | B3: ALFACE AMERICANA cx 7,5 kg | C3: cx 7,5 kg | D3: 7.5 | E3: 35 | F3: =E3/D3 -> 4.6666667 | G3: 46310
A4: alface | B4: ALFACE CRESPA GRANDE cx 7 kg | C4: cx 7 kg | D4: 7 | E4: 30 | F4: =E4/D4 -> 4.2857143 | G4: 46310
A5: alface | B5: ALFACE CRESPA MEDIO cx 6 kg | C5: cx 6 kg | D5: 6 | E5: 20 | F5: =E5/D5 -> 3.3333333 | G5: 46310
A6: alface | B6: ALFACE HIDROPONICO cx 7 kg | C6: cx 7 kg | D6: 7 | E6: 35 | F6: =E6/D6 -> 5 | G6: 46310
A7: alface | B7: ALFACE LISA MEDIO cx 6 kg | C7: cx 6 kg | D7: 6 | E7: 20 | F7: =E7/D7 -> 3.3333333 | G7: 46310
A8: alface | B8: ALFACE ROXA GRANDE cx 7 kg | C8: cx 7 kg | D8: 7 | E8: 30 | F8: =E8/D8 -> 4.2857143 | G8: 46310
A9: alho-poró | B9: ALHO PORRO MAÇO 4 UNID mç 2 kg | C9: mç 2 kg | D9: 2 | E9: 15 | F9: =E9/D9 -> 7.5 | G9: 46310
A10: almeirão | B10: ALMEIRAO C. ESPADA mç 300 g | C10: mç 300 g | D10: 0.3 | E10: 2 | F10: =E10/D10 -> 6.6666667 | G10: 46310
A11: almeirão | B11: ALMEIRAO PÃO DE AÇUCAR mç 400 g | C11: mç 400 g | D11: 0.4 | E11: 2 | F11: =E11/D11 -> 5 | G11: 46310
A12: brócolis | B12: COUVE BROCOLO dz 6 kg | C12: dz 6 kg | D12: 6 | E12: 35 | F12: =E12/D12 -> 5.8333333 | G12: 46310
A13: brócolis | B13: COUVE BROCOLO mç 500 g | C13: mç 500 g | D13: 0.5 | E13: 3 | F13: =E13/D13 -> 6 | G13: 46310
... A124: tangerina ponkan | B124: TANGERINA PONKAN GRAUDA cx 20 kg | C124: cx 20 kg | D124: 20 | E124: 100 | F124: =E124/D124 -> 5 | G124: 46310
A126: Fonte: CEASA-PR/DITEC, preço mais comum, unidade Curitiba; R$/kg = preço da embalagem ÷ peso da embalagem.
